Workbook

Sheet アルカナ名
A1: ID | B1: 位置 | C1: 名前 | D1: 画像
A2: 0 | B2: Front | C2: 愚者
A3: 0 | B3: Back | C3: 愚者
A4: 1 | B4: Front | C4: 魔術師
A5: 1 | B5: Back | C5: 魔術師
A6: 2 | B6: Front | C6: 女教皇
A7: 2 | B7: Back | C7: 女教皇
A8: 3 | B8: Front | C8: 女帝
A9: 3 | B9: Back | C9: 女帝
A10: 4 | B10: Front | C10: 皇帝
A11: 4 | B11: Back | C11: 皇帝
A12: 5 | B12: Front | C12: 教皇
A13: 5 | B13: Back | C13: 教皇
... A45: 21 | B45: Back | C45: 世界

Sheet ArcanaData
A1: ID | B1: 位置 | C1: 名前 | D1: 発動条件 | E1: クールタイム | F1: エフェクト | G1: 効果音 | H1: 説明 | I1: Key
A2: =INDEX(ArcanaMaster[ID], ROW()-1) -> 0 | B2: =VLOOKUP(ArcanaMaster[[#This Row],[位置]],選択用フィールド!$I$2:$J$3,2,FALSE) -> 1 | C2: =ArcanaMaster[[#This Row],[名前]] -> 愚者 | D2: =VLOOKUP(InputData[[#This Row],[発動条件]],選択用フィールド!$A$2:$B$6,2,FALSE) -> StartEffect | E2: =InputData[[#This Row],[クールタイム]] -> -1 | F2: =選択用フィールド!$G$2&"/"&InputData[[#This Row],[エフェクト]] -> Effect/Arcana/ | G2: =InputData[[#This Row],[効果音]] -> 0 | H2: =InputData[[#This Row],[説明]] -> HPを上げるカード | I2: ="Arcana"&TEXT(A2, "00")&VLOOKUP(ArcanaData[[#This Row],[名前]],選択用フィールド!$D$2:$E$23,2,FALSE)&ArcanaMaster[[#This Row],[位置]] -> Arcana00FoolFront
A3: =INDEX(ArcanaMaster[ID], ROW()-1) -> 0 | B3: =VLOOKUP(ArcanaMaster[[#This Row],[位置]],選択用フィールド!$I$2:$J$3,2,FALSE) -> -1 | C3: =ArcanaMaster[[#This Row],[名前]] -> 愚者 | D3: =VLOOKUP(InputData[[#This Row],[発動条件]],選択用フィールド!$A$2:$B$6,2,FALSE) -> StartEffect | E3: =InputData[[#This Row],[クールタイム]] -> -1 | F3: =選択用フィールド!$G$2&"/"&InputData[[#This Row],[エフェクト]] -> Effect/Arcana/ | G3: =InputData[[#This Row],[効果音]] -> 0 | H3: =InputData[[#This Row],[説明]] -> 何も持たなくても勝てることが証明できるカード | I3: ="Arcana"&TEXT(A3, "00")&VLOOKUP(ArcanaData[[#This Row],[名前]],選択用フィールド!$D$2:$E$23,2,FALSE)&ArcanaMaster[[#This Row],[位置]] -> Arcana00FoolBack
A4: =INDEX(ArcanaMaster[ID], ROW()-1) -> 1 | B4: =VLOOKUP(ArcanaMaster[[#This Row],[位置]],選択用フィールド!$I$2:$J$3,2,FALSE) -> 1 | C4: =ArcanaMaster[[#This Row],[名前]] -> 魔術師 | D4: =VLOOKUP(InputData[[#This Row],[発動条件]],選択用フィールド!$A$2:$B$6,2,FALSE) -> StartEffect | E4: =InputData[[#This Row],[クールタイム]] -> -1 | F4: =選択用フィールド!$G$2&"/"&InputData[[#This Row],[エフェクト]] -> Effect/Arcana/ | G4: =InputData[[#This Row],[効果音]] -> 0 | H4: =InputData[[#This Row],[説明]] -> 防御無視を付与できるカード | I4: ="Arcana"&TEXT(A4, "00")&VLOOKUP(ArcanaData[[#This Row],[名前]],選択用フィールド!$D$2:$E$23,2,FALSE)&ArcanaMaster[[#This Row],[位置]] -> Arcana01MagicianFront
A5: =INDEX(ArcanaMaster[ID], ROW()-1) -> 1 | B5: =VLOOKUP(ArcanaMaster[[#This Row],[位置]],選択用フィールド!$I$2:$J$3,2,FALSE) -> -1 | C5: =ArcanaMaster[[#This Row],[名前]] -> 魔術師 | D5: =VLOOKUP(InputData[[#This Row],[発動条件]],選択用フィールド!$A$2:$B$6,2,FALSE) -> Command | E5: =InputData[[#This Row],[クールタイム]] -> 30 | F5: =選択用フィールド!$G$2&"/"&InputData[[#This Row],[エフェクト]] -> Effect/Arcana/Monster | G5: =InputData[[#This Row],[効果音]] -> 0 | H5: =InputData[[#This Row],[説明]] -> 召喚物を出せるカード | I5: ="Arcana"&TEXT(A5, "00")&VLOOKUP(ArcanaData[[#This Row],[名前]],選択用フィールド!$D$2:$E$23,2,FALSE)&ArcanaMaster[[#This Row],[位置]] -> Arcana01MagicianBack
A6: =INDEX(ArcanaMaster[ID], ROW()-1) -> 2 | B6: =VLOOKUP(ArcanaMaster[[#This Row],[位置]],選択用フィールド!$I$2:$J$3,2,FALSE) -> 1 | C6: =ArcanaMaster[[#This Row],[名前]] -> 女教皇 | D6: =VLOOKUP(InputData[[#This Row],[発動条件]],選択用フィールド!$A$2:$B$6,2,FALSE) -> StartEffect | E6: =InputData[[#This Row],[クールタイム]] -> -1 | F6: =選択用フィールド!$G$2&"/"&InputData[[#This Row],[エフェクト]] -> Effect/Arcana/ | G6: =InputData[[#This Row],[効果音]] -> 0 | H6: =InputData[[#This Row],[説明]] -> 時間がたつほど強くなるカード | I6: ="Arcana"&TEXT(A6, "00")&VLOOKUP(ArcanaData[[#This Row],[名前]],選択用フィールド!$D$2:$E$23,2,FALSE)&ArcanaMaster[[#This Row],[位置]] -> Arcana02HighPriestessFront
A7: =INDEX(ArcanaMaster[ID], ROW()-1) -> 2 | B7: =VLOOKUP(ArcanaMaster[[#This Row],[位置]],選択用フィールド!$I$2:$J$3,2,FALSE) -> -1 | C7: =ArcanaMaster[[#This Row],[名前]] -> 女教皇 | D7: =VLOOKUP(InputData[[#This Row],[発動条件]],選択用フィールド!$A$2:$B$6,2,FALSE) -> StartEffect | E7: =InputData[[#This Row],[クールタイム]] -> -1 | F7: =選択用フィールド!$G$2&"/"&InputData[[#This Row],[エフェクト]] -> Effect/Arcana/ | G7: =InputData[[#This Row],[効果音]] -> 0 | H7: =InputData[[#This Row],[説明]] -> 時間がたつほど弱くなるカード | I7: ="Arcana"&TEXT(A7, "00")&VLOOKUP(ArcanaData[[#This Row],[名前]],選択用フィールド!$D$2:$E$23,2,FALSE)&ArcanaMaster[[#This Row],[位置]] -> Arcana02HighPriestessBack
A8: =INDEX(ArcanaMaster[ID], ROW()-1) -> 3 | B8: =VLOOKUP(ArcanaMaster[[#This Row],[位置]],選択用フィールド!$I$2:$J$3,2,FALSE) -> 1 | C8: =ArcanaMaster[[#This Row],[名前]] -> 女帝 | D8: =VLOOKUP(InputData[[#This Row],[発動条件]],選択用フィールド!$A$2:$B$6,2,FALSE) -> StartEffect | E8: =InputData[[#This Row],[クールタイム]] -> -1 | F8: =選択用フィールド!$G$2&"/"&InputData[[#This Row],[エフェクト]] -> Effect/Arcana/ | G8: =InputData[[#This Row],[効果音]] -> 0 | H8: =InputData[[#This Row],[説明]] -> 自然治癒を付与するカード | I8: ="Arcana"&TEXT(A8, "00")&VLOOKUP(ArcanaData[[#This Row],[名前]],選択用フィールド!$D$2:$E$23,2,FALSE)&ArcanaMaster[[#This Row],[位置]] -> Arcana03EmpressFront
A9: =INDEX(ArcanaMaster[ID], ROW()-1) -> 3 | B9: =VLOOKUP(ArcanaMaster[[#This Row],[位置]],選択用フィールド!$I$2:$J$3,2,FALSE) -> -1 | C9: =ArcanaMaster[[#This Row],[名前]] -> 女帝 | D9: =VLOOKUP(InputData[[#This Row],[発動条件]],選択用フィールド!$A$2:$B$6,2,FALSE) -> StartEffect | E9: =InputData[[#This Row],[クールタイム]] -> -1 | F9: =選択用フィールド!$G$2&"/"&InputData[[#This Row],[エフェクト]] -> Effect/Arcana/Dice | G9: =InputData[[#This Row],[効果音]] -> 0 | H9: =InputData[[#This Row],[説明]] -> ランダムでバフやデバフがつくカード | I9: ="Arcana"&TEXT(A9, "00")&VLOOKUP(ArcanaData[[#This Row],[名前]],選択用フィールド!$D$2:$E$23,2,FALSE)&ArcanaMaster[[#This Row],[位置]] -> Arcana03EmpressBack
A10: =INDEX(ArcanaMaster[ID], ROW()-1) -> 4 | B10: =VLOOKUP(ArcanaMaster[[#This Row],[位置]],選択用フィールド!$I$2:$J$3,2,FALSE) -> 1 | C10: =ArcanaMaster[[#This Row],[名前]] -> 皇帝 | D10: =VLOOKUP(InputData[[#This Row],[発動条件]],選択用フィールド!$A$2:$B$6,2,FALSE) -> Command | E10: =InputData[[#This Row],[クールタイム]] -> 60 | F10: =選択用フィールド!$G$2&"/"&InputData[[#This Row],[エフェクト]] -> Effect/Arcana/ | G10: =InputData[[#This Row],[効果音]] -> 0 | H10: =InputData[[#This Row],[説明]] -> スキル禁止を付与するカード | I10: ="Arcana"&TEXT(A10, "00")&VLOOKUP(ArcanaData[[#This Row],[名前]],選択用フィールド!$D$2:$E$23,2,FALSE)&ArcanaMaster[[#This Row],[位置]] -> Arcana04EmperorFront
A11: =INDEX(ArcanaMaster[ID], ROW()-1) -> 4 | B11: =VLOOKUP(ArcanaMaster[[#This Row],[位置]],選択用フィールド!$I$2:$J$3,2,FALSE) -> -1 | C11: =ArcanaMaster[[#This Row],[名前]] -> 皇帝 | D11: =VLOOKUP(InputData[[#This Row],[発動条件]],選択用フィールド!$A$2:$B$6,2,FALSE) -> StartEffect | E11: =InputData[[#This Row],[クールタイム]] -> -1 | F11: =選択用フィールド!$G$2&"/"&InputData[[#This Row],[エフェクト]] -> Effect/Arcana/ | G11: =InputData[[#This Row],[効果音]] -> 0 | H11: =InputData[[#This Row],[説明]] -> 通常攻撃は振れないがダメージが上がるカード | I11: ="Arcana"&TEXT(A11, "00")&VLOOKUP(ArcanaData[[#This Row],[名前]],選択用フィールド!$D$2:$E$23,2,FALSE)&ArcanaMaster[[#This Row],[位置]] -> Arcana04EmperorBack
A12: =INDEX(ArcanaMaster[ID], ROW()-1) -> 5 | B12: =VLOOKUP(ArcanaMaster[[#This Row],[位置]],選択用フィールド!$I$2:$J$3,2,FALSE) -> 1 | C12: =ArcanaMaster[[#This Row],[名前]] -> 教皇 | D12: =VLOOKUP(InputData[[#This Row],[発動条件]],選択用フィールド!$A$2:$B$6,2,FALSE) -> StartEffect | E12: =InputData[[#This Row],[クールタイム]] -> -1 | F12: =選択用フィールド!$G$2&"/"&InputData[[#This Row],[エフェクト]] -> Effect/Arcana/ | G12: =InputData[[#This Row],[効果音]] -> 0 | H12: =InputData[[#This Row],[説明]] -> スキルの当たり判定が大きくなるカード | I12: ="Arcana"&TEXT(A12, "00")&VLOOKUP(ArcanaData[[#This Row],[名前]],選択用フィールド!$D$2:$E$23,2,FALSE)&ArcanaMaster[[#This Row],[位置]] -> Arcana05HierophantFront
A13: =INDEX(ArcanaMaster[ID], ROW()-1) -> 5 | B13: =VLOOKUP(ArcanaMaster[[#This Row],[位置]],選択用フィールド!$I$2:$J$3,2,FALSE) -> -1 | C13: =ArcanaMaster[[#This Row],[名前]] -> 教皇 | D13: =VLOOKUP(InputData[[#This Row],[発動条件]],選択用フィールド!$A$2:$B$6,2,FALSE) -> Command | E13: =InputData[[#This Row],[クールタイム]] -> 30 | F13: =選択用フィールド!$G$2&"/"&InputData[[#This Row],[エフェクト]] -> Effect/Arcana/ | G13: =InputData[[#This Row],[効果音]] -> 0 | H13: =InputData[[#This Row],[説明]] -> 敵の行動を逆にするカード | I13: ="Arcana"&TEXT(A13, "00")&VLOOKUP(ArcanaData[[#This Row],[名前]],選択用フィールド!$D$2:$E$23,2,FALSE)&ArcanaMaster[[#This Row],[位置]] -> Arcana05HierophantBack
... A45: =INDEX(ArcanaMaster[ID], ROW()-1) -> 21 | B45: =VLOOKUP(ArcanaMaster[[#This Row],[位置]],選択用フィールド!$I$2:$J$3,2,FALSE) -> -1 | C45: =ArcanaMaster[[#This Row],[名前]] -> 世界 | D45: =VLOOKUP(InputData[[#This Row],[発動条件]],選択用フィールド!$A$2:$B$6,2,FALSE) -> StartEffect | E45: =InputData[[#This Row],[クールタイム]] -> -1 | F45: =選択用フィールド!$G$2&"/"&InputData[[#This Row],[エフェクト]] -> Effect/Arcana/ | G45: =InputData[[#This Row],[効果音]] -> 0 | H45: =InputData[[#This Row],[説明]] -> 次元移動ができるカード | I45: ="Arcana"&TEXT(A45, "00")&VLOOKUP(ArcanaData[[#This Row],[名前]],選択用フィールド!$D$2:$E$23,2,FALSE)&ArcanaMaster[[#This Row],[位置]] -> Arcana21WorldBack

Sheet 選択用フィールド
A1: 発動条件 | D1: アルカナ名 | G1: エフェクト名 | I1: 向き
A2: スタート時に発動 | B2: StartEffect | D2: 愚者 | E2: Fool | G2: Effect/Arcana | I2: Front | J2: 1
A3: ボタンで発動 | B3: Command | D3: 魔術師 | E3: Magician | I3: Back | J3: -1
A4: スキル発動時に発動 | B4: SkillEffect | D4: 女教皇 | E4: HighPriestess | G4: 効果音名
A5: ダメージで発動 | B5: DamageEffect | D5: 女帝 | E5: Empress | G5: Audio/SE
A6: 死亡時に発動 | B6: DeathEffect | D6: 皇帝 | E6: Emperor
D7: 教皇 | E7: Hierophant
D8: 恋人 | E8: Lovers
D9: 戦車 | E9: Chariot
D10: 力 | E10: Strength
D11: 隠者 | E11: Hermit
D12: 運命の輪 | E12: WheelOfFortune
D13: 正義 | E13: Justice
D14: つるされた男 | E14: HangedMan
D15: 死神 | E15: Death
D16: 節制 | E16: Temperance
D17: 悪魔 | E17: Devil
D18: 塔 | E18: Tower
... D23: 世界 | E23: World

Sheet InputFile(Arcana)
A1: 名前 | B1: 位置 | C1: 発動条件 | D1: クールタイム | E1: エフェクト | F1: 効果音 | G1: 説明
A2: =ArcanaMaster[[#This Row],[名前]] -> 愚者 | B2: =IF(ArcanaMaster[[#This Row],[位置]]="Front", "正位置", "逆位置") -> 正位置 | C2: スタート時に発動 | D2: -1 | G2: HPを上げるカード
A3: =ArcanaMaster[[#This Row],[名前]] -> 愚者 | B3: =IF(ArcanaMaster[[#This Row],[位置]]="Front", "正位置", "逆位置") -> 逆位置 | C3: スタート時に発動 | D3: -1 | G3: 何も持たなくても勝てることが証明できるカード
A4: =ArcanaMaster[[#This Row],[名前]] -> 魔術師 | B4: =IF(ArcanaMaster[[#This Row],[位置]]="Front", "正位置", "逆位置") -> 正位置 | C4: スタート時に発動 | D4: -1 | G4: 防御無視を付与できるカード
A5: =ArcanaMaster[[#This Row],[名前]] -> 魔術師 | B5: =IF(ArcanaMaster[[#This Row],[位置]]="Front", "正位置", "逆位置") -> 逆位置 | C5: ボタンで発動 | D5: 30 | E5: Monster | G5: 召喚物を出せるカード
A6: =ArcanaMaster[[#This Row],[名前]] -> 女教皇 | B6: =IF(ArcanaMaster[[#This Row],[位置]]="Front", "正位置", "逆位置") -> 正位置 | C6: スタート時に発動 | D6: -1 | G6: 時間がたつほど強くなるカード
A7: =ArcanaMaster[[#This Row],[名前]] -> 女教皇 | B7: =IF(ArcanaMaster[[#This Row],[位置]]="Front", "正位置", "逆位置") -> 逆位置 | C7: スタート時に発動 | D7: -1 | G7: 時間がたつほど弱くなるカード
A8: =ArcanaMaster[[#This Row],[名前]] -> 女帝 | B8: =IF(ArcanaMaster[[#This Row],[位置]]="Front", "正位置", "逆位置") -> 正位置 | C8: スタート時に発動 | D8: -1 | G8: 自然治癒を付与するカード
A9: =ArcanaMaster[[#This Row],[名前]] -> 女帝 | B9: =IF(ArcanaMaster[[#This Row],[位置]]="Front", "正位置", "逆位置") -> 逆位置 | C9: スタート時に発動 | D9: -1 | E9: Dice | G9: ランダムでバフやデバフがつくカード
A10: =ArcanaMaster[[#This Row],[名前]] -> 皇帝 | B10: =IF(ArcanaMaster[[#This Row],[位置]]="Front", "正位置", "逆位置") -> 正位置 | C10: ボタンで発動 | D10: 60 | G10: スキル禁止を付与するカード
A11: =ArcanaMaster[[#This Row],[名前]] -> 皇帝 | B11: =IF(ArcanaMaster[[#This Row],[位置]]="Front", "正位置", "逆位置") -> 逆位置 | C11: スタート時に発動 | D11: -1 | G11: 通常攻撃は振れないがダメージが上がるカード
A12: =ArcanaMaster[[#This Row],[名前]] -> 教皇 | B12: =IF(ArcanaMaster[[#This Row],[位置]]="Front", "正位置", "逆位置") -> 正位置 | C12: スタート時に発動 | D12: -1 | G12: スキルの当たり判定が大きくなるカード
A13: =ArcanaMaster[[#This Row],[名前]] -> 教皇 | B13: =IF(ArcanaMaster[[#This Row],[位置]]="Front", "正位置", "逆位置") -> 逆位置 | C13: ボタンで発動 | D13: 30 | G13: 敵の行動を逆にするカード
A14: =ArcanaMaster[[#This Row],[名前]] -> 恋人 | B14: =IF(ArcanaMaster[[#This Row],[位置]]="Front", "正位置", "逆位置") -> 正位置 | C14: ボタンで発動 | D14: 30 | G14: 敵がダメージを肩代わりしてくれるカード
A15: =ArcanaMaster[[#This Row],[名前]] -> 恋人 | B15: =IF(ArcanaMaster[[#This Row],[位置]]="Front", "正位置", "逆位置") -> 逆位置 | C15: ボタンで発動 | D15: 40 | G15: 自分以外の視界を暗くするカード
A16: =ArcanaMaster[[#This Row],[名前]] -> 戦車 | B16: =IF(ArcanaMaster[[#This Row],[位置]]="Front", "正位置", "逆位置") -> 正位置 | C16: スタート時に発動 | D16: -1 | G16: 移動速度が速くなるカード
A17: =ArcanaMaster[[#This Row],[名前]] -> 戦車 | B17: =IF(ArcanaMaster[[#This Row],[位置]]="Front", "正位置", "逆位置") -> 逆位置 | C17: スタート時に発動 | D17: -1 | G17: スキル発動の予備動作の時間が半分になるカード
A18: =ArcanaMaster[[#This Row],[名前]] -> 力 | B18: =IF(ArcanaMaster[[#This Row],[位置]]="Front", "正位置", "逆位置") -> 正位置 | C18: スタート時に発動 | D18: -1 | G18: 攻撃力を上げるカード
A19: =ArcanaMaster[[#This Row],[名前]] -> 力 | B19: =IF(ArcanaMaster[[#This Row],[位置]]="Front", "正位置", "逆位置") -> 逆位置 | C19: ダメージで発動 | D19: -1 | G19: HPが減るたび他のステータスが上がるカード
A20: =ArcanaMaster[[#This Row],[名前]] -> 隠者 | B20: =IF(ArcanaMaster[[#This Row],[位置]]="Front", "正位置", "逆位置") -> 正位置 | C20: スタート時に発動 | D20: -1 | G20: 人が回復したHPを半分奪うカード
A21: =ArcanaMaster[[#This Row],[名前]] -> 隠者 | B21: =IF(ArcanaMaster[[#This Row],[位置]]="Front", "正位置", "逆位置") -> 逆位置 | C21: スタート時に発動 | D21: -1 | E21: Trap | G21: トラップを設置するカード
A22: =ArcanaMaster[[#This Row],[名前]] -> 運命の輪 | B22: =IF(ArcanaMaster[[#This Row],[位置]]="Front", "正位置", "逆位置") -> 正位置 | C22: ボタンで発動 | D22: 15 | G22: ランダムな場所にテレポートするカード
A23: =ArcanaMaster[[#This Row],[名前]] -> 運命の輪 | B23: =IF(ArcanaMaster[[#This Row],[位置]]="Front", "正位置", "逆位置") -> 逆位置 | C23: ボタンで発動 | D23: 30 | G23: 敵をジャンプ禁止にするカード
A24: =ArcanaMaster[[#This Row],[名前]] -> 正義 | B24: =IF(ArcanaMaster[[#This Row],[位置]]="Front", "正位置", "逆位置") -> 正位置 | C24: ボタンで発動 | D24: 60 | G24: 敵に一定のダメージを与えるカード
A25: =ArcanaMaster[[#This Row],[名前]] -> 正義 | B25: =IF(ArcanaMaster[[#This Row],[位置]]="Front", "正位置", "逆位置") -> 逆位置 | C25: ボタンで発動 | D25: 30 | G25: カウンターを付与するカード
A26: =ArcanaMaster[[#This Row],[名前]] -> つるされた男 | B26: =IF(ArcanaMaster[[#This Row],[位置]]="Front", "正位置", "逆位置") -> 正位置 | C26: ボタンで発動 | D26: 30 | G26: 視点が反対になるカード
A27: =ArcanaMaster[[#This Row],[名前]] -> つるされた男 | B27: =IF(ArcanaMaster[[#This Row],[位置]]="Front", "正位置", "逆位置") -> 逆位置 | C27: スタート時に発動 | D27: -1 | G27: 運気が上がるカード
A28: =ArcanaMaster[[#This Row],[名前]] -> 死神 | B28: =IF(ArcanaMaster[[#This Row],[位置]]="Front", "正位置", "逆位置") -> 正位置 | C28: スタート時に発動 | D28: -1 | G28: #
A29: =ArcanaMaster[[#This Row],[名前]] -> 死神 | B29: =IF(ArcanaMaster[[#This Row],[位置]]="Front", "正位置", "逆位置") -> 逆位置 | C29: ダメージで発動 | D29: -1 | G29: 相手にダメージを与えたときに回復するカード
A30: =ArcanaMaster[[#This Row],[名前]] -> 節制 | B30: =IF(ArcanaMaster[[#This Row],[位置]]="Front", "正位置", "逆位置") -> 正位置 | C30: スタート時に発動 | D30: -1 | G30: 自分のスキルのクールタイムを早くするカード
A31: =ArcanaMaster[[#This Row],[名前]] -> 節制 | B31: =IF(ArcanaMaster[[#This Row],[位置]]="Front", "正位置", "逆位置") -> 逆位置 | C31: スタート時に発動 | D31: -1 | G31: 敵のクールタイムを遅くするカード
A32: =ArcanaMaster[[#This Row],[名前]] -> 悪魔 | B32: =IF(ArcanaMaster[[#This Row],[位置]]="Front", "正位置", "逆位置") -> 正位置 | C32: スタート時に発動 | D32: -1 | G32: #
A33: =ArcanaMaster[[#This Row],[名前]] -> 悪魔 | B33: =IF(ArcanaMaster[[#This Row],[位置]]="Front", "正位置", "逆位置") -> 逆位置 | C33: ボタンで発動 | D33: 5 | G33: 自分のバフ・デバフを消し、その分攻撃力が上がるカード
A34: =ArcanaMaster[[#This Row],[名前]] -> 塔 | B34: =IF(ArcanaMaster[[#This Row],[位置]]="Front", "正位置", "逆位置") -> 正位置 | C34: ボタンで発動 | D34: 90 | E34: Turret | G34: タレットがおけるカード
A35: =ArcanaMaster[[#This Row],[名前]] -> 塔 | B35: =IF(ArcanaMaster[[#This Row],[位置]]="Front", "正位置", "逆位置") -> 逆位置 | C35: スタート時に発動 | D35: -1 | G35: 確率で数秒後にスキルが再発動するカード
A36: =ArcanaMaster[[#This Row],[名前]] -> 星 | B36: =IF(ArcanaMaster[[#This Row],[位置]]="Front", "正位置", "逆位置") -> 正位置 | C36: ボタンで発動 | D36: 50 | G36: あなたが注目を浴びるカード
A37: =ArcanaMaster[[#This Row],[名前]] -> 星 | B37: =IF(ArcanaMaster[[#This Row],[位置]]="Front", "正位置", "逆位置") -> 逆位置 | C37: ボタンで発動 | D37: 60 | G37: 無敵を付与するカード
A38: =ArcanaMaster[[#This Row],[名前]] -> 月 | B38: =IF(ArcanaMaster[[#This Row],[位置]]="Front", "正位置", "逆位置") -> 正位置 | C38: スタート時に発動 | D38: -1 | G38: #
A39: =ArcanaMaster[[#This Row],[名前]] -> 月 | B39: =IF(ArcanaMaster[[#This Row],[位置]]="Front", "正位置", "逆位置") -> 逆位置 | C39: スタート時に発動 | D39: -1 | G39: #
A40: =ArcanaMaster[[#This Row],[名前]] -> 太陽 | B40: =IF(ArcanaMaster[[#This Row],[位置]]="Front", "正位置", "逆位置") -> 正位置 | C40: ボタンで発動 | D40: 45 | G40: 晴れ日和になるカード
...
